---

layout: post

title:  golang学习笔记(8)

tag: go语言

---

# golang学习笔记(8)

---

## 1 错误处理

error类型其实也是一个接口类型，这个接口只包含了一个方法Error。Error不接收参数，但是会返回一个错误信息。

如果通过`err = errors.New()`的方式定义错误，就可以在接口中返回该错误，在主函数中，通过判断err是否为nil，就可以确定函数是否存在错误。

通过上述方法定义出的err的静态类型为error，而动态类型是在errors包中的包级私有类型*errorString.

也就是说，errorString类型拥有的一个指针方法实现了error接口的Error方法，这个方法被调用后，会返回我们之前说的错误信息。

当我们想通过模板化的方式生成错误信息，并得到错误值时，可以使用fmt.Errorf函数。该函数所做的其实就是先调用fmt.Sprintf函数，得到确切的错误信息；再调用errors.New函数，得到包含该错误信息的error类型值，最后返回该值。

### 1 错误类型判断

对于错误类型判断，一般有三种方式：

1.对于类型在已知范围内的一系列错误值，一般使用类型断言表达式或类型switch语句来判断；对于类型在已知范围内的一系列错误值，一般使用类型断言表达式或类型switch语句来判断。

代码示例：

```go
func underlyingError(err error) error {
    switch err := err.(type) {
    case *os.PathError:
        return err.Err
    case *os.LinkError:
        return err.Err
    case *os.SyscallError:
        return err.Err
    case *exec.Error:
        return err.Err
    }
    return err
}
````

这个方法的作用就是，判断是否存在对应的错误，如果有，就把这个错误的Err字段返回，否则就原样返回错误信息。

2.对于已有相应变量且类型相同的一系列错误值，一般直接使用判等操作来判断。

```go
printError := func(i int, err error) {
    if err == nil {
        fmt.Println("nil error")
        return
    }
    err = underlyingError(err)
    switch err {
    case os.ErrClosed:
        fmt.Printf("error(closed)[%d]: %s\n", i, err)
    case os.ErrInvalid:
        fmt.Printf("error(invalid)[%d]: %s\n", i, err)
    case os.ErrPermission:
        fmt.Printf("error(permission)[%d]: %s\n", i, err)
    }
}
```

3.对于没有相应变量且类型未知的一系列错误值，只能使用其错误信息的字符串表示形式来做判断。

如果前两种方法都无法判断，那么就只能通过实际的错误信息来进行判断了。

不过我们可以通过Error方法，拿到错误信息。

## 2 panic

panic代表的是运行时恐慌，对比到java中就是异常信息，而且指的是会导致程序崩溃的异常信息。在java中此类信息只会抛出异常，程序依旧在jvm中运行，而go中的panic会导致主goroutine停止。

和java类似，panic的错误信息会首先打印最基层的错误行数，也就是报错的位置，然后一级一级地往上报，直到到达goroutine，也可以理解为main中。

除此之外，Go中的内建函数panic是专门用来引发panic异常的。

代码示例：

```go
package main

import (
	"errors"
	"fmt"
)

func main() {
	fmt.Println("Enter function main.")
	caller()
	fmt.Println("Exit function main.")
}

func caller() {
	fmt.Println("Enter function caller.")
	panic(errors.New("something wrong")) // 正例。
	panic(fmt.Println)                   // 反例。
	fmt.Println("Exit function caller.")
}
```

引发的错误信息如下：

```go
Enter function main.
Enter function caller.
panic: something wrong

goroutine 1 [running]:
main.caller()
	J:/go/projects/Golang_Puzzlers/src/puzzlers/article19/q2/demo49.go:16 +0xc5
main.main()
	J:/go/projects/Golang_Puzzlers/src/puzzlers/article19/q2/demo49.go:10 +0x8a
```

panic和error的区别在于，panic导致的异常会导致程序崩溃，是致命的，而error是非致命的，可以忽略。这一点和java不同。

recover函数就是专门用于恢复panic的，避免程序崩溃。recover函数的运行方法为：`p := recover()`

但是这里有一个悖论：只有有了panic，recover函数才会获取到数据，但panic发生之后，后面的代码都不会执行，而是会直接向前查找，写在后面的recover函数就不会执行，因此，需要用到defer函数。

在今天之前，defer函数的用法我一直停留在关闭流等延迟操作上，没想到可以用在这里。通过defer延迟执行recover函数，在发生了panic后，程序中止前，执行defer中的recover函数，就可以对panic进行保护。

具体示例：

```go
package main

import (
	"errors"
	"fmt"
)

func main() {
	fmt.Println("Enter function main.")

	defer func() {
		fmt.Println("Enter defer function.")

		// recover函数的正确用法。
		if p := recover(); p != nil {
			fmt.Printf("panic: %s\n", p)
		}

		fmt.Println("Exit defer function.")
	}()

	// recover函数的错误用法。
	fmt.Printf("no panic: %v\n", recover())

	// 引发panic。
	panic(errors.New("something wrong"))

	// recover函数的错误用法。
	p := recover()
	fmt.Printf("panic: %s\n", p)

	fmt.Println("Exit function main.")
}
```

除此之外，需要注意defer函数的存储形式是栈，也就是说，最后的defer函数会先执行，前面的defer函数会后执行。

